[0;33m--- esp-idf-monitor 1.3.3 on /dev/ttyACM0 115200 ---[0m
[0;33m--- Quit: Ctrl+] | Menu: Ctrl+T | Help: Ctrl+T followed by Ctrl+H ---[0m
[0;33m0x40375914: call_start_cpu1 at /home/filipe/esp/esp-idf/components/esp_system/port/cpu_start.c:154
[0m
[0;33m0x40375914: call_start_cpu1 at /home/filipe/esp/esp-idf/components/esp_system/port/cpu_start.c:154
[0m
[0;33m0x40375e2a: panic_abort at /home/filipe/esp/esp-idf/components/esp_system/panic.c:452
[0m
[0;33m0x4037e15d: esp_system_abort at /home/filipe/esp/esp-idf/components/esp_system/port/esp_system_chip.c:84
[0m
[0;33m0x40380e82: vApplicationStackOverflowHook at /home/filipe/esp/esp-idf/components/freertos/FreeRTOS-Kernel/portable/xtensa/port.c:581
[0m
[0;33m0x4037f7d3: vTaskSwitchContext at /home/filipe/esp/esp-idf/components/freertos/FreeRTOS-Kernel/tasks.c:3728
[0m
[0;33m0x40380fd0: _frxt_dispatch at /home/filipe/esp/esp-idf/components/freertos/FreeRTOS-Kernel/portable/xtensa/portasm.S:450
[0m
[0;33m0x40380fc6: _frxt_int_exit at /home/filipe/esp/esp-idf/components/freertos/FreeRTOS-Kernel/portable/xtensa/portasm.S:245
[0m
[0;33m0x40375d2c: esp_restart_noos_dig at /home/filipe/esp/esp-idf/components/esp_system/port/esp_system_chip.c:57 (discriminator 1)
[0m
[0;33m0x40375914: call_start_cpu1 at /home/filipe/esp/esp-idf/components/esp_system/port/cpu_start.c:154
[0m
[0;33m0x40375914: call_start_cpu1 at /home/filipe/esp/esp-idf/components/esp_system/port/cpu_start.c:154
[0m
[1;31mNone[0m
[0;33mWaiting for the device to reconnect[0mException in thread Thread-2 (_run_outer):
Traceback (most recent call last):
  File "/home/filipe/.espressif/python_env/idf5.1_py3.10_env/lib/python3.10/site-packages/esp_idf_monitor/base/serial_reader.py", line 76, in run
    data = self.serial.read(self.serial.in_waiting or 1)
  File "/home/filipe/.espressif/python_env/idf5.1_py3.10_env/lib/python3.10/site-packages/serial/serialposix.py", line 595, in read
    raise SerialException(
serial.serialutil.SerialException: device reports readiness to read but returned no data (device disconnected or multiple access on port?)

During handling of the above exception, another exception occurred:

Traceback (most recent call last):
  File "/home/filipe/.espressif/python_env/idf5.1_py3.10_env/lib/python3.10/site-packages/esp_idf_monitor/base/serial_reader.py", line 83, in run
    self.close_serial()
  File "/home/filipe/.espressif/python_env/idf5.1_py3.10_env/lib/python3.10/site-packages/esp_idf_monitor/base/serial_reader.py", line 104, in close_serial
    self._disable_closing_wait_or_discard_data()
  File "/home/filipe/.espressif/python_env/idf5.1_py3.10_env/lib/python3.10/site-packages/esp_idf_monitor/base/serial_reader.py", line 120, in _disable_closing_wait_or_discard_data
    buf = fcntl.ioctl(self.serial.fd, termios.TIOCGSERIAL, buf)
OSError: [Errno 5] Input/output error

During handling of the above exception, another exception occurred:

Traceback (most recent call last):
  File "/usr/lib/python3.10/threading.py", line 1016, in _bootstrap_inner
    self.run()
  File "/usr/lib/python3.10/threading.py", line 953, in run
    self._target(*self._args, **self._kwargs)
  File "/home/filipe/.espressif/python_env/idf5.1_py3.10_env/lib/python3.10/site-packages/esp_idf_monitor/base/stoppable_thread.py", line 47, in _run_outer
    self.run()
  File "/home/filipe/.espressif/python_env/idf5.1_py3.10_env/lib/python3.10/site-packages/esp_idf_monitor/base/serial_reader.py", line 100, in run
    self.close_serial()
  File "/home/filipe/.espressif/python_env/idf5.1_py3.10_env/lib/python3.10/site-packages/esp_idf_monitor/base/serial_reader.py", line 104, in close_serial
    self._disable_closing_wait_or_discard_data()
  File "/home/filipe/.espressif/python_env/idf5.1_py3.10_env/lib/python3.10/site-packages/esp_idf_monitor/base/serial_reader.py", line 120, in _disable_closing_wait_or_discard_data
    buf = fcntl.ioctl(self.serial.fd, termios.TIOCGSERIAL, buf)
OSError: [Errno 5] Input/output error
[0m
